Internal Server Error: /login/
Traceback (most recent call last):
  File "/usr/local/lib/python3.8/site-packages/django/db/backends/utils.py", line 89, in _execute
    return self.cursor.execute(sql, params)
psycopg2.errors.UndefinedColumn: column users_user.expiry_date does not exist
LINE 1: ...sers_user"."quota_cpu", "users_user"."quota_gpu", "users_use...
                                                             ^


The above exception was the direct cause of the following exception:

Traceback (most recent call last):
  File "/usr/local/lib/python3.8/site-packages/django/core/handlers/exception.py", line 55, in inner
    response = get_response(request)
  File "/usr/src/app/./escriptorium/middleware.py", line 30, in __call__
    if not request.user.is_authenticated:
  File "/usr/local/lib/python3.8/site-packages/django/utils/functional.py", line 266, in inner
    self._setup()
  File "/usr/local/lib/python3.8/site-packages/django/utils/functional.py", line 419, in _setup
    self._wrapped = self._setupfunc()
  File "/usr/local/lib/python3.8/site-packages/django/contrib/auth/middleware.py", line 25, in <lambda>
    request.user = SimpleLazyObject(lambda: get_user(request))
  File "/usr/local/lib/python3.8/site-packages/django/contrib/auth/middleware.py", line 11, in get_user
    request._cached_user = auth.get_user(request)
  File "/usr/local/lib/python3.8/site-packages/django/contrib/auth/__init__.py", line 198, in get_user
    user = backend.get_user(user_id)
  File "/usr/local/lib/python3.8/site-packages/django/contrib/auth/backends.py", line 161, in get_user
    user = UserModel._default_manager.get(pk=user_id)
  File "/usr/local/lib/python3.8/site-packages/django/db/models/manager.py", line 87, in manager_method
    return getattr(self.get_queryset(), name)(*args, **kwargs)
  File "/usr/local/lib/python3.8/site-packages/django/db/models/query.py", line 633, in get
    num = len(clone)
  File "/usr/local/lib/python3.8/site-packages/django/db/models/query.py", line 380, in __len__
    self._fetch_all()
  File "/usr/local/lib/python3.8/site-packages/django/db/models/query.py", line 1881, in _fetch_all
    self._result_cache = list(self._iterable_class(self))
  File "/usr/local/lib/python3.8/site-packages/django/db/models/query.py", line 91, in __iter__
    results = compiler.execute_sql(
  File "/usr/local/lib/python3.8/site-packages/django/db/models/sql/compiler.py", line 1562, in execute_sql
    cursor.execute(sql, params)
  File "/usr/local/lib/python3.8/site-packages/django/db/backends/utils.py", line 67, in execute
    return self._execute_with_wrappers(
  File "/usr/local/lib/python3.8/site-packages/django/db/backends/utils.py", line 80, in _execute_with_wrappers
    return executor(sql, params, many, context)
  File "/usr/local/lib/python3.8/site-packages/django/db/backends/utils.py", line 89, in _execute
    return self.cursor.execute(sql, params)
  File "/usr/local/lib/python3.8/site-packages/django/db/utils.py", line 91, in __exit__
    raise dj_exc_value.with_traceback(traceback) from exc_value
  File "/usr/local/lib/python3.8/site-packages/django/db/backends/utils.py", line 89, in _execute
    return self.cursor.execute(sql, params)
django.db.utils.ProgrammingError: column users_user.expiry_date does not exist
LINE 1: ...sers_user"."quota_cpu", "users_user"."quota_gpu", "users_use...
                                                             ^

Internal Server Error: /favicon.ico
Internal Server Error: /
Traceback (most recent call last):
  File "/usr/local/lib/python3.8/site-packages/django/db/backends/utils.py", line 89, in _execute
    return self.cursor.execute(sql, params)
psycopg2.errors.UndefinedColumn: column users_user.expiry_date does not exist
LINE 1: ...sers_user"."quota_cpu", "users_user"."quota_gpu", "users_use...
                                                             ^


The above exception was the direct cause of the following exception:

Traceback (most recent call last):
  File "/usr/local/lib/python3.8/site-packages/django/core/handlers/exception.py", line 55, in inner
    response = get_response(request)
  File "/usr/src/app/./escriptorium/middleware.py", line 30, in __call__
    if not request.user.is_authenticated:
  File "/usr/local/lib/python3.8/site-packages/django/utils/functional.py", line 266, in inner
    self._setup()
  File "/usr/local/lib/python3.8/site-packages/django/utils/functional.py", line 419, in _setup
    self._wrapped = self._setupfunc()
  File "/usr/local/lib/python3.8/site-packages/django/contrib/auth/middleware.py", line 25, in <lambda>
    request.user = SimpleLazyObject(lambda: get_user(request))
  File "/usr/local/lib/python3.8/site-packages/django/contrib/auth/middleware.py", line 11, in get_user
    request._cached_user = auth.get_user(request)
  File "/usr/local/lib/python3.8/site-packages/django/contrib/auth/__init__.py", line 198, in get_user
    user = backend.get_user(user_id)
  File "/usr/local/lib/python3.8/site-packages/django/contrib/auth/backends.py", line 161, in get_user
    user = UserModel._default_manager.get(pk=user_id)
  File "/usr/local/lib/python3.8/site-packages/django/db/models/manager.py", line 87, in manager_method
    return getattr(self.get_queryset(), name)(*args, **kwargs)
  File "/usr/local/lib/python3.8/site-packages/django/db/models/query.py", line 633, in get
    num = len(clone)
  File "/usr/local/lib/python3.8/site-packages/django/db/models/query.py", line 380, in __len__
    self._fetch_all()
  File "/usr/local/lib/python3.8/site-packages/django/db/models/query.py", line 1881, in _fetch_all
    self._result_cache = list(self._iterable_class(self))
  File "/usr/local/lib/python3.8/site-packages/django/db/models/query.py", line 91, in __iter__
    results = compiler.execute_sql(
  File "/usr/local/lib/python3.8/site-packages/django/db/models/sql/compiler.py", line 1562, in execute_sql
    cursor.execute(sql, params)
  File "/usr/local/lib/python3.8/site-packages/django/db/backends/utils.py", line 67, in execute
    return self._execute_with_wrappers(
  File "/usr/local/lib/python3.8/site-packages/django/db/backends/utils.py", line 80, in _execute_with_wrappers
    return executor(sql, params, many, context)
  File "/usr/local/lib/python3.8/site-packages/django/db/backends/utils.py", line 89, in _execute
    return self.cursor.execute(sql, params)
  File "/usr/local/lib/python3.8/site-packages/django/db/utils.py", line 91, in __exit__
    raise dj_exc_value.with_traceback(traceback) from exc_value
  File "/usr/local/lib/python3.8/site-packages/django/db/backends/utils.py", line 89, in _execute
    return self.cursor.execute(sql, params)
django.db.utils.ProgrammingError: column users_user.expiry_date does not exist
LINE 1: ...sers_user"."quota_cpu", "users_user"."quota_gpu", "users_use...
                                                             ^

Internal Server Error: /
Traceback (most recent call last):
  File "/usr/local/lib/python3.8/site-packages/django/db/backends/utils.py", line 89, in _execute
    return self.cursor.execute(sql, params)
psycopg2.errors.UndefinedColumn: column users_user.expiry_date does not exist
LINE 1: ...sers_user"."quota_cpu", "users_user"."quota_gpu", "users_use...
                                                             ^


The above exception was the direct cause of the following exception:

Traceback (most recent call last):
  File "/usr/local/lib/python3.8/site-packages/django/core/handlers/exception.py", line 55, in inner
    response = get_response(request)
  File "/usr/src/app/./escriptorium/middleware.py", line 30, in __call__
    if not request.user.is_authenticated:
  File "/usr/local/lib/python3.8/site-packages/django/utils/functional.py", line 266, in inner
    self._setup()
  File "/usr/local/lib/python3.8/site-packages/django/utils/functional.py", line 419, in _setup
    self._wrapped = self._setupfunc()
  File "/usr/local/lib/python3.8/site-packages/django/contrib/auth/middleware.py", line 25, in <lambda>
    request.user = SimpleLazyObject(lambda: get_user(request))
  File "/usr/local/lib/python3.8/site-packages/django/contrib/auth/middleware.py", line 11, in get_user
    request._cached_user = auth.get_user(request)
  File "/usr/local/lib/python3.8/site-packages/django/contrib/auth/__init__.py", line 198, in get_user
    user = backend.get_user(user_id)
  File "/usr/local/lib/python3.8/site-packages/django/contrib/auth/backends.py", line 161, in get_user
    user = UserModel._default_manager.get(pk=user_id)
  File "/usr/local/lib/python3.8/site-packages/django/db/models/manager.py", line 87, in manager_method
    return getattr(self.get_queryset(), name)(*args, **kwargs)
  File "/usr/local/lib/python3.8/site-packages/django/db/models/query.py", line 633, in get
    num = len(clone)
  File "/usr/local/lib/python3.8/site-packages/django/db/models/query.py", line 380, in __len__
    self._fetch_all()
  File "/usr/local/lib/python3.8/site-packages/django/db/models/query.py", line 1881, in _fetch_all
    self._result_cache = list(self._iterable_class(self))
  File "/usr/local/lib/python3.8/site-packages/django/db/models/query.py", line 91, in __iter__
    results = compiler.execute_sql(
  File "/usr/local/lib/python3.8/site-packages/django/db/models/sql/compiler.py", line 1562, in execute_sql
    cursor.execute(sql, params)
  File "/usr/local/lib/python3.8/site-packages/django/db/backends/utils.py", line 67, in execute
    return self._execute_with_wrappers(
  File "/usr/local/lib/python3.8/site-packages/django/db/backends/utils.py", line 80, in _execute_with_wrappers
    return executor(sql, params, many, context)
  File "/usr/local/lib/python3.8/site-packages/django/db/backends/utils.py", line 89, in _execute
    return self.cursor.execute(sql, params)
  File "/usr/local/lib/python3.8/site-packages/django/db/utils.py", line 91, in __exit__
    raise dj_exc_value.with_traceback(traceback) from exc_value
  File "/usr/local/lib/python3.8/site-packages/django/db/backends/utils.py", line 89, in _execute
    return self.cursor.execute(sql, params)
django.db.utils.ProgrammingError: column users_user.expiry_date does not exist
LINE 1: ...sers_user"."quota_cpu", "users_user"."quota_gpu", "users_use...
                                                             ^

Internal Server Error: /
Traceback (most recent call last):
  File "/usr/local/lib/python3.8/site-packages/django/db/backends/utils.py", line 89, in _execute
    return self.cursor.execute(sql, params)
psycopg2.errors.UndefinedColumn: column users_user.expiry_date does not exist
LINE 1: ...sers_user"."quota_cpu", "users_user"."quota_gpu", "users_use...
                                                             ^


The above exception was the direct cause of the following exception:

Traceback (most recent call last):
  File "/usr/local/lib/python3.8/site-packages/django/core/handlers/exception.py", line 55, in inner
    response = get_response(request)
  File "/usr/src/app/./escriptorium/middleware.py", line 30, in __call__
    if not request.user.is_authenticated:
  File "/usr/local/lib/python3.8/site-packages/django/utils/functional.py", line 266, in inner
    self._setup()
  File "/usr/local/lib/python3.8/site-packages/django/utils/functional.py", line 419, in _setup
    self._wrapped = self._setupfunc()
  File "/usr/local/lib/python3.8/site-packages/django/contrib/auth/middleware.py", line 25, in <lambda>
    request.user = SimpleLazyObject(lambda: get_user(request))
  File "/usr/local/lib/python3.8/site-packages/django/contrib/auth/middleware.py", line 11, in get_user
    request._cached_user = auth.get_user(request)
  File "/usr/local/lib/python3.8/site-packages/django/contrib/auth/__init__.py", line 198, in get_user
    user = backend.get_user(user_id)
  File "/usr/local/lib/python3.8/site-packages/django/contrib/auth/backends.py", line 161, in get_user
    user = UserModel._default_manager.get(pk=user_id)
  File "/usr/local/lib/python3.8/site-packages/django/db/models/manager.py", line 87, in manager_method
    return getattr(self.get_queryset(), name)(*args, **kwargs)
  File "/usr/local/lib/python3.8/site-packages/django/db/models/query.py", line 633, in get
    num = len(clone)
  File "/usr/local/lib/python3.8/site-packages/django/db/models/query.py", line 380, in __len__
    self._fetch_all()
  File "/usr/local/lib/python3.8/site-packages/django/db/models/query.py", line 1881, in _fetch_all
    self._result_cache = list(self._iterable_class(self))
  File "/usr/local/lib/python3.8/site-packages/django/db/models/query.py", line 91, in __iter__
    results = compiler.execute_sql(
  File "/usr/local/lib/python3.8/site-packages/django/db/models/sql/compiler.py", line 1562, in execute_sql
    cursor.execute(sql, params)
  File "/usr/local/lib/python3.8/site-packages/django/db/backends/utils.py", line 67, in execute
    return self._execute_with_wrappers(
  File "/usr/local/lib/python3.8/site-packages/django/db/backends/utils.py", line 80, in _execute_with_wrappers
    return executor(sql, params, many, context)
  File "/usr/local/lib/python3.8/site-packages/django/db/backends/utils.py", line 89, in _execute
    return self.cursor.execute(sql, params)
  File "/usr/local/lib/python3.8/site-packages/django/db/utils.py", line 91, in __exit__
    raise dj_exc_value.with_traceback(traceback) from exc_value
  File "/usr/local/lib/python3.8/site-packages/django/db/backends/utils.py", line 89, in _execute
    return self.cursor.execute(sql, params)
django.db.utils.ProgrammingError: column users_user.expiry_date does not exist
LINE 1: ...sers_user"."quota_cpu", "users_user"."quota_gpu", "users_use...
                                                             ^

Internal Server Error: /
Traceback (most recent call last):
  File "/usr/local/lib/python3.8/site-packages/django/db/backends/utils.py", line 89, in _execute
    return self.cursor.execute(sql, params)
psycopg2.errors.UndefinedColumn: column users_user.expiry_date does not exist
LINE 1: ...sers_user"."quota_cpu", "users_user"."quota_gpu", "users_use...
                                                             ^


The above exception was the direct cause of the following exception:

Traceback (most recent call last):
  File "/usr/local/lib/python3.8/site-packages/django/core/handlers/exception.py", line 55, in inner
    response = get_response(request)
  File "/usr/src/app/./escriptorium/middleware.py", line 30, in __call__
    if not request.user.is_authenticated:
  File "/usr/local/lib/python3.8/site-packages/django/utils/functional.py", line 266, in inner
    self._setup()
  File "/usr/local/lib/python3.8/site-packages/django/utils/functional.py", line 419, in _setup
    self._wrapped = self._setupfunc()
  File "/usr/local/lib/python3.8/site-packages/django/contrib/auth/middleware.py", line 25, in <lambda>
    request.user = SimpleLazyObject(lambda: get_user(request))
  File "/usr/local/lib/python3.8/site-packages/django/contrib/auth/middleware.py", line 11, in get_user
    request._cached_user = auth.get_user(request)
  File "/usr/local/lib/python3.8/site-packages/django/contrib/auth/__init__.py", line 198, in get_user
    user = backend.get_user(user_id)
  File "/usr/local/lib/python3.8/site-packages/django/contrib/auth/backends.py", line 161, in get_user
    user = UserModel._default_manager.get(pk=user_id)
  File "/usr/local/lib/python3.8/site-packages/django/db/models/manager.py", line 87, in manager_method
    return getattr(self.get_queryset(), name)(*args, **kwargs)
  File "/usr/local/lib/python3.8/site-packages/django/db/models/query.py", line 633, in get
    num = len(clone)
  File "/usr/local/lib/python3.8/site-packages/django/db/models/query.py", line 380, in __len__
    self._fetch_all()
  File "/usr/local/lib/python3.8/site-packages/django/db/models/query.py", line 1881, in _fetch_all
    self._result_cache = list(self._iterable_class(self))
  File "/usr/local/lib/python3.8/site-packages/django/db/models/query.py", line 91, in __iter__
    results = compiler.execute_sql(
  File "/usr/local/lib/python3.8/site-packages/django/db/models/sql/compiler.py", line 1562, in execute_sql
    cursor.execute(sql, params)
  File "/usr/local/lib/python3.8/site-packages/django/db/backends/utils.py", line 67, in execute
    return self._execute_with_wrappers(
  File "/usr/local/lib/python3.8/site-packages/django/db/backends/utils.py", line 80, in _execute_with_wrappers
    return executor(sql, params, many, context)
  File "/usr/local/lib/python3.8/site-packages/django/db/backends/utils.py", line 89, in _execute
    return self.cursor.execute(sql, params)
  File "/usr/local/lib/python3.8/site-packages/django/db/utils.py", line 91, in __exit__
    raise dj_exc_value.with_traceback(traceback) from exc_value
  File "/usr/local/lib/python3.8/site-packages/django/db/backends/utils.py", line 89, in _execute
    return self.cursor.execute(sql, params)
django.db.utils.ProgrammingError: column users_user.expiry_date does not exist
LINE 1: ...sers_user"."quota_cpu", "users_user"."quota_gpu", "users_use...
                                                             ^

Internal Server Error: /project/ww1-service-records/documents/
Traceback (most recent call last):
  File "/usr/local/lib/python3.8/site-packages/django/core/handlers/exception.py", line 55, in inner
    response = get_response(request)
  File "/usr/local/lib/python3.8/site-packages/django/core/handlers/base.py", line 197, in _get_response
    response = wrapped_callback(request, *callback_args, **callback_kwargs)
  File "/usr/local/lib/python3.8/site-packages/django/views/generic/base.py", line 105, in view
    return self.dispatch(request, *args, **kwargs)
  File "/usr/local/lib/python3.8/site-packages/django/contrib/auth/mixins.py", line 73, in dispatch
    return super().dispatch(request, *args, **kwargs)
  File "/usr/local/lib/python3.8/site-packages/django/views/generic/base.py", line 144, in dispatch
    return handler(request, *args, **kwargs)
  File "/usr/local/lib/python3.8/site-packages/django/views/generic/list.py", line 154, in get
    self.object_list = self.get_queryset()
  File "/usr/src/app/apps/core/views.py", line 437, in get_queryset
    self.project = (Project.objects
  File "/usr/local/lib/python3.8/site-packages/django/db/models/manager.py", line 87, in manager_method
    return getattr(self.get_queryset(), name)(*args, **kwargs)
  File "/usr/local/lib/python3.8/site-packages/django/db/models/query.py", line 637, in get
    raise self.model.DoesNotExist(
core.models.Project.DoesNotExist: Project matching query does not exist.
